Workbook

Sheet Master
A1: Team | B1: Roster Name | C1: Simple Name | D1: Offical ID | E1: Initial_Name | F1: First Name | G1: Last Name | H1: Vald Name | I1: Kinexon Name | J1: Perch Name | K1: Data Hub Name | L1: Position | M1: Position Class | N1: Offical ID2 | O1: Starters
A2: Active | B2: Lamont Johnson-Burrell | C2: Lamont Johnson-Burrell | D2: Johnson-Burrell_Lamont_25 | E2: =CONCATENATE(Master_Roster[[#This Row],[Last Name]],", ",MID(Master_Roster[[#This Row],[First Name]],1,2)) -> Johnson-Burrell, La | F2: Lamont | G2: Johnson-Burrell | H2: Lamont Johnson-Burrell | I2: Lamont Johnson-Burrell | J2: Lamont Johnson-Burrell | K2: Johnson-Burrell, Lamont | L2: =IFERROR(VLOOKUP(Master_Roster[[#This Row],[Offical ID]],'Online Roster'!L$3:M$112,2,FALSE),"") -> CB | M2: {=IFERROR(_xlfn.IFS(OR(Master_Roster[[#This Row],[Position]]="OL",Master_Roster[[#This Row],[Position]]="DL"),"Bigs",OR(Master_Roster[[#This Row],[Position]]="ILB",Master_Roster[[#This Row],[Position]]="OLB",Master_Roster[[#This Row],[Position]]="TE",Master_Roster[[#This Row],[Position]]="QB",Master_Roster[[#This Row],[Position]]="RB",Master_Roster[[#This Row],[Position]]="FB"),"Mids",OR(Master_Roster[[#This Row],[Position]]="WR",Master_Roster[[#This Row],[Position]]="CB",Master_Roster[[#This Row],[Position]]="S"),"Skills",OR(Master_Roster[[#This Row],[Position]]="K",Master_Roster[[#This Row],[Position]]="P",Master_Roster[[#This Row],[Position]]="LS",),"Spec"),"")} -> Skills | N2: =Master_Roster[[#This Row],[Offical ID]] -> Johnson-Burrell_Lamont_25 | O2: Back-Up
A3: Active | B3: Caleb Reese | C3: Caleb Reese | D3: Reese_Caleb_25 | E3: =CONCATENATE(Master_Roster[[#This Row],[Last Name]],", ",MID(Master_Roster[[#This Row],[First Name]],1,2)) -> Reese, Ca | F3: Caleb | G3: Reese | H3: Caleb Reese | I3: Caleb Reese | J3: =Master_Roster[[#This Row],[Simple Name]] -> Caleb Reese | K3: Reese, Caleb | L3: =IFERROR(VLOOKUP(Master_Roster[[#This Row],[Offical ID]],'Online Roster'!L$3:M$112,2,FALSE),"") -> CB | M3: {=IFERROR(_xlfn.IFS(OR(Master_Roster[[#This Row],[Position]]="OL",Master_Roster[[#This Row],[Position]]="DL"),"Bigs",OR(Master_Roster[[#This Row],[Position]]="ILB",Master_Roster[[#This Row],[Position]]="OLB",Master_Roster[[#This Row],[Position]]="TE",Master_Roster[[#This Row],[Position]]="QB",Master_Roster[[#This Row],[Position]]="RB",Master_Roster[[#This Row],[Position]]="FB"),"Mids",OR(Master_Roster[[#This Row],[Position]]="WR",Master_Roster[[#This Row],[Position]]="CB",Master_Roster[[#This Row],[Position]]="S"),"Skills",OR(Master_Roster[[#This Row],[Position]]="K",Master_Roster[[#This Row],[Position]]="P",Master_Roster[[#This Row],[Position]]="LS",),"Spec"),"")} -> Skills | N3: =Master_Roster[[#This Row],[Offical ID]] -> Reese_Caleb_25 | O3: Back-Up
A4: Active | B4: Jayden Robinson | C4: Jayden Robinson | D4: Robinson_Jayden_25 | E4: =CONCATENATE(Master_Roster[[#This Row],[Last Name]],", ",MID(Master_Roster[[#This Row],[First Name]],1,2)) -> Robinson, Ja | F4: Jayden | G4: Robinson | H4: Jayden Robinson | I4: Jayden Robinson | J4: Jayden Robinson | K4: Robinson, Jayden | L4: =IFERROR(VLOOKUP(Master_Roster[[#This Row],[Offical ID]],'Online Roster'!L$3:M$112,2,FALSE),"") -> CB | M4: {=IFERROR(_xlfn.IFS(OR(Master_Roster[[#This Row],[Position]]="OL",Master_Roster[[#This Row],[Position]]="DL"),"Bigs",OR(Master_Roster[[#This Row],[Position]]="ILB",Master_Roster[[#This Row],[Position]]="OLB",Master_Roster[[#This Row],[Position]]="TE",Master_Roster[[#This Row],[Position]]="QB",Master_Roster[[#This Row],[Position]]="RB",Master_Roster[[#This Row],[Position]]="FB"),"Mids",OR(Master_Roster[[#This Row],[Position]]="WR",Master_Roster[[#This Row],[Position]]="CB",Master_Roster[[#This Row],[Position]]="S"),"Skills",OR(Master_Roster[[#This Row],[Position]]="K",Master_Roster[[#This Row],[Position]]="P",Master_Roster[[#This Row],[Position]]="LS",),"Spec"),"")} -> Skills | N4: =Master_Roster[[#This Row],[Offical ID]] -> Robinson_Jayden_25 | O4: Back-Up
A5: Active | B5: Adam Taylor | C5: Adam Taylor | D5: Taylor_Adam_25 | E5: =CONCATENATE(Master_Roster[[#This Row],[Last Name]],", ",MID(Master_Roster[[#This Row],[First Name]],1,2)) -> Taylor, Ad | F5: Adam | G5: Taylor | H5: Adam Taylor | I5: Adam Taylor | J5: Adam Taylor | K5: Taylor, Adam | L5: =IFERROR(VLOOKUP(Master_Roster[[#This Row],[Offical ID]],'Online Roster'!L$3:M$112,2,FALSE),"") -> CB | M5: {=IFERROR(_xlfn.IFS(OR(Master_Roster[[#This Row],[Position]]="OL",Master_Roster[[#This Row],[Position]]="DL"),"Bigs",OR(Master_Roster[[#This Row],[Position]]="ILB",Master_Roster[[#This Row],[Position]]="OLB",Master_Roster[[#This Row],[Position]]="TE",Master_Roster[[#This Row],[Position]]="QB",Master_Roster[[#This Row],[Position]]="RB",Master_Roster[[#This Row],[Position]]="FB"),"Mids",OR(Master_Roster[[#This Row],[Position]]="WR",Master_Roster[[#This Row],[Position]]="CB",Master_Roster[[#This Row],[Position]]="S"),"Skills",OR(Master_Roster[[#This Row],[Position]]="K",Master_Roster[[#This Row],[Position]]="P",Master_Roster[[#This Row],[Position]]="LS",),"Spec"),"")} -> Skills | N5: =Master_Roster[[#This Row],[Offical ID]] -> Taylor_Adam_25 | O5: Back-Up
A6: Active | B6: Nash Burkhart | C6: Nash Burkhart | D6: Burkhart_Nash_25 | E6: =CONCATENATE(Master_Roster[[#This Row],[Last Name]],", ",MID(Master_Roster[[#This Row],[First Name]],1,2)) -> Burkhart, Na | F6: Nash | G6: Burkhart | H6: Nash Burkart | I6: Nash Burkart | J6: Nash Burkart | K6: Burkart, Nash | L6: CB | M6: Skills | N6: =Master_Roster[[#This Row],[Offical ID]] -> Burkhart_Nash_25 | O6: Back-Up
A7: Active | B7: Dejuan Butler | C7: Dejuan Butler | D7: Butler_Dejuan_25 | E7: =CONCATENATE(Master_Roster[[#This Row],[Last Name]],", ",MID(Master_Roster[[#This Row],[First Name]],1,2)) -> Butler, De | F7: Dejuan | G7: Butler | H7: DeJuan Butler | I7: Dejuan Butler | J7: Dejuan Butler | K7: Butler, DeJuan | L7: =IFERROR(VLOOKUP(Master_Roster[[#This Row],[Offical ID]],'Online Roster'!L$3:M$112,2,FALSE),"") -> CB | M7: {=IFERROR(_xlfn.IFS(OR(Master_Roster[[#This Row],[Position]]="OL",Master_Roster[[#This Row],[Position]]="DL"),"Bigs",OR(Master_Roster[[#This Row],[Position]]="ILB",Master_Roster[[#This Row],[Position]]="OLB",Master_Roster[[#This Row],[Position]]="TE",Master_Roster[[#This Row],[Position]]="QB",Master_Roster[[#This Row],[Position]]="RB",Master_Roster[[#This Row],[Position]]="FB"),"Mids",OR(Master_Roster[[#This Row],[Position]]="WR",Master_Roster[[#This Row],[Position]]="CB",Master_Roster[[#This Row],[Position]]="S"),"Skills",OR(Master_Roster[[#This Row],[Position]]="K",Master_Roster[[#This Row],[Position]]="P",Master_Roster[[#This Row],[Position]]="LS",),"Spec"),"")} -> Skills | N7: =Master_Roster[[#This Row],[Offical ID]] -> Butler_Dejuan_25 | O7: Rotation
A8: Archive 25 | B8: Jordan Atkinson | C8: Jordan Atkinson | D8: Atkinson_Jordan_25 | E8: =CONCATENATE(Master_Roster[[#This Row],[Last Name]],", ",MID(Master_Roster[[#This Row],[First Name]],1,2)) -> Atkinson, Jo | F8: Jordan | G8: Atkinson | H8: Jordan Atkinson | I8: Jordan Atkinson | K8: Atkinson, Jordan | L8: =IFERROR(VLOOKUP(Master_Roster[[#This Row],[Offical ID]],'Online Roster'!L$3:M$112,2,FALSE),"") -> OLB | M8: {=IFERROR(_xlfn.IFS(OR(Master_Roster[[#This Row],[Position]]="OL",Master_Roster[[#This Row],[Position]]="DL"),"Bigs",OR(Master_Roster[[#This Row],[Position]]="ILB",Master_Roster[[#This Row],[Position]]="OLB",Master_Roster[[#This Row],[Position]]="TE",Master_Roster[[#This Row],[Position]]="QB",Master_Roster[[#This Row],[Position]]="RB",Master_Roster[[#This Row],[Position]]="FB"),"Mids",OR(Master_Roster[[#This Row],[Position]]="WR",Master_Roster[[#This Row],[Position]]="CB",Master_Roster[[#This Row],[Position]]="S"),"Skills",OR(Master_Roster[[#This Row],[Position]]="K",Master_Roster[[#This Row],[Position]]="P",Master_Roster[[#This Row],[Position]]="LS",),"Spec"),"")} -> Mids | N8: =Master_Roster[[#This Row],[Offical ID]] -> Atkinson_Jordan_25
A9: Active | B9: Warren Smith, Jr. | C9: Warren Smith | D9: Smith_Warren_25 | E9: =CONCATENATE(Master_Roster[[#This Row],[Last Name]],", ",MID(Master_Roster[[#This Row],[First Name]],1,2)) -> Smith, Wa | F9: Warren | G9: Smith | H9: Warren Smith | I9: Warren Smith | J9: Warren Smith | K9: Smith, Warren | L9: =IFERROR(VLOOKUP(Master_Roster[[#This Row],[Offical ID]],'Online Roster'!L$3:M$112,2,FALSE),"") -> CB | M9: {=IFERROR(_xlfn.IFS(OR(Master_Roster[[#This Row],[Position]]="OL",Master_Roster[[#This Row],[Position]]="DL"),"Bigs",OR(Master_Roster[[#This Row],[Position]]="ILB",Master_Roster[[#This Row],[Position]]="OLB",Master_Roster[[#This Row],[Position]]="TE",Master_Roster[[#This Row],[Position]]="QB",Master_Roster[[#This Row],[Position]]="RB",Master_Roster[[#This Row],[Position]]="FB"),"Mids",OR(Master_Roster[[#This Row],[Position]]="WR",Master_Roster[[#This Row],[Position]]="CB",Master_Roster[[#This Row],[Position]]="S"),"Skills",OR(Master_Roster[[#This Row],[Position]]="K",Master_Roster[[#This Row],[Position]]="P",Master_Roster[[#This Row],[Position]]="LS",),"Spec"),"")} -> Skills | N9: =Master_Roster[[#This Row],[Offical ID]] -> Smith_Warren_25 | O9: Starter
A10: Active | B10: Jalen Williams | C10: Jalen Williams | D10: Williams_Jalen_25 | E10: =CONCATENATE(Master_Roster[[#This Row],[Last Name]],", ",MID(Master_Roster[[#This Row],[First Name]],1,2)) -> Williams, Ja | F10: Jalen | G10: Williams | H10: Jalen Williams | I10: Jalen Williams | J10: Jalen Williams | K10: Williams, Jalen | L10: CB | M10: {=IFERROR(_xlfn.IFS(OR(Master_Roster[[#This Row],[Position]]="OL",Master_Roster[[#This Row],[Position]]="DL"),"Bigs",OR(Master_Roster[[#This Row],[Position]]="ILB",Master_Roster[[#This Row],[Position]]="OLB",Master_Roster[[#This Row],[Position]]="TE",Master_Roster[[#This Row],[Position]]="QB",Master_Roster[[#This Row],[Position]]="RB",Master_Roster[[#This Row],[Position]]="FB"),"Mids",OR(Master_Roster[[#This Row],[Position]]="WR",Master_Roster[[#This Row],[Position]]="CB",Master_Roster[[#This Row],[Position]]="S"),"Skills",OR(Master_Roster[[#This Row],[Position]]="K",Master_Roster[[#This Row],[Position]]="P",Master_Roster[[#This Row],[Position]]="LS",),"Spec"),"")} -> Skills | N10: =Master_Roster[[#This Row],[Offical ID]] -> Williams_Jalen_25 | O10: Rotation
A11: Active | B11: Ricky Lee III | C11: Ricky Lee | D11: Lee_Ricky_25 | E11: =CONCATENATE(Master_Roster[[#This Row],[Last Name]],", ",MID(Master_Roster[[#This Row],[First Name]],1,2)) -> Lee, Ri | F11: Ricky | G11: Lee | H11: Ricky Lee | I11: Ricky Lee | J11: Ricky Lee | K11: Lee, Ricky | L11: =IFERROR(VLOOKUP(Master_Roster[[#This Row],[Offical ID]],'Online Roster'!L$3:M$112,2,FALSE),"") -> CB | M11: {=IFERROR(_xlfn.IFS(OR(Master_Roster[[#This Row],[Position]]="OL",Master_Roster[[#This Row],[Position]]="DL"),"Bigs",OR(Master_Roster[[#This Row],[Position]]="ILB",Master_Roster[[#This Row],[Position]]="OLB",Master_Roster[[#This Row],[Position]]="TE",Master_Roster[[#This Row],[Position]]="QB",Master_Roster[[#This Row],[Position]]="RB",Master_Roster[[#This Row],[Position]]="FB"),"Mids",OR(Master_Roster[[#This Row],[Position]]="WR",Master_Roster[[#This Row],[Position]]="CB",Master_Roster[[#This Row],[Position]]="S"),"Skills",OR(Master_Roster[[#This Row],[Position]]="K",Master_Roster[[#This Row],[Position]]="P",Master_Roster[[#This Row],[Position]]="LS",),"Spec"),"")} -> Skills | N11: =Master_Roster[[#This Row],[Offical ID]] -> Lee_Ricky_25 | O11: Starter
A12: Active | B12: Elias Mullican | C12: Elias Mullican | D12: Mullican_Elias_25 | E12: =CONCATENATE(Master_Roster[[#This Row],[Last Name]],", ",MID(Master_Roster[[#This Row],[First Name]],1,2)) -> Mullican, El | F12: Elias | G12: Mullican | H12: Elias Mullican | I12: Elias Mullican | J12: Elias Mullican | K12: Mullican, Elias | L12: =IFERROR(VLOOKUP(Master_Roster[[#This Row],[Offical ID]],'Online Roster'!L$3:M$112,2,FALSE),"") -> CB | M12: {=IFERROR(_xlfn.IFS(OR(Master_Roster[[#This Row],[Position]]="OL",Master_Roster[[#This Row],[Position]]="DL"),"Bigs",OR(Master_Roster[[#This Row],[Position]]="ILB",Master_Roster[[#This Row],[Position]]="OLB",Master_Roster[[#This Row],[Position]]="TE",Master_Roster[[#This Row],[Position]]="QB",Master_Roster[[#This Row],[Position]]="RB",Master_Roster[[#This Row],[Position]]="FB"),"Mids",OR(Master_Roster[[#This Row],[Position]]="WR",Master_Roster[[#This Row],[Position]]="CB",Master_Roster[[#This Row],[Position]]="S"),"Skills",OR(Master_Roster[[#This Row],[Position]]="K",Master_Roster[[#This Row],[Position]]="P",Master_Roster[[#This Row],[Position]]="LS",),"Spec"),"")} -> Skills | N12: =Master_Roster[[#This Row],[Offical ID]] -> Mullican_Elias_25 | O12: Starter
A13: Active | B13: Jason Oliver | C13: Jason Oliver | D13: Oliver_Jason_25 | E13: =CONCATENATE(Master_Roster[[#This Row],[Last Name]],", ",MID(Master_Roster[[#This Row],[First Name]],1,2)) -> Oliver, Ja | F13: Jason | G13: Oliver | H13: Jason Oliver | I13: Jason Oliver | J13: Jason Oliver | K13: Oliver, Jason | L13: =IFERROR(VLOOKUP(Master_Roster[[#This Row],[Offical ID]],'Online Roster'!L$3:M$112,2,FALSE),"") -> CB | M13: {=IFERROR(_xlfn.IFS(OR(Master_Roster[[#This Row],[Position]]="OL",Master_Roster[[#This Row],[Position]]="DL"),"Bigs",OR(Master_Roster[[#This Row],[Position]]="ILB",Master_Roster[[#This Row],[Position]]="OLB",Master_Roster[[#This Row],[Position]]="TE",Master_Roster[[#This Row],[Position]]="QB",Master_Roster[[#This Row],[Position]]="RB",Master_Roster[[#This Row],[Position]]="FB"),"Mids",OR(Master_Roster[[#This Row],[Position]]="WR",Master_Roster[[#This Row],[Position]]="CB",Master_Roster[[#This Row],[Position]]="S"),"Skills",OR(Master_Roster[[#This Row],[Position]]="K",Master_Roster[[#This Row],[Position]]="P",Master_Roster[[#This Row],[Position]]="LS",),"Spec"),"")} -> Skills | N13: =Master_Roster[[#This Row],[Offical ID]] -> Oliver_Jason_25 | O13: Rotation
A14: Active | B14: Jordan Jefferson | C14: Jordan Jefferson | D14: Jefferson_Jordan_25 | E14: =CONCATENATE(Master_Roster[[#This Row],[Last Name]],", ",MID(Master_Roster[[#This Row],[First Name]],1,2)) -> Jefferson, Jo | F14: Jordan | G14: Jefferson | H14: Jordan Jefferson | I14: Jordan Jefferson | J14: Jordan Jefferson | K14: Jefferson, Jordan | L14: =IFERROR(VLOOKUP(Master_Roster[[#This Row],[Offical ID]],'Online Roster'!L$3:M$112,2,FALSE),"") -> DL | M14: {=IFERROR(_xlfn.IFS(OR(Master_Roster[[#This Row],[Position]]="OL",Master_Roster[[#This Row],[Position]]="DL"),"Bigs",OR(Master_Roster[[#This Row],[Position]]="ILB",Master_Roster[[#This Row],[Position]]="OLB",Master_Roster[[#This Row],[Position]]="TE",Master_Roster[[#This Row],[Position]]="QB",Master_Roster[[#This Row],[Position]]="RB",Master_Roster[[#This Row],[Position]]="FB"),"Mids",OR(Master_Roster[[#This Row],[Position]]="WR",Master_Roster[[#This Row],[Position]]="CB",Master_Roster[[#This Row],[Position]]="S"),"Skills",OR(Master_Roster[[#This Row],[Position]]="K",Master_Roster[[#This Row],[Position]]="P",Master_Roster[[#This Row],[Position]]="LS",),"Spec"),"")} -> Bigs | N14: =Master_Roster[[#This Row],[Offical ID]] -> Jefferson_Jordan_25 | O14: Back-Up
A15: Active | B15: Malachi Kindle | C15: Malachi Kindle | D15: Kindle_Malachi_25 | E15: =CONCATENATE(Master_Roster[[#This Row],[Last Name]],", ",MID(Master_Roster[[#This Row],[First Name]],1,2)) -> Kindle, Ma | F15: Malachi | G15: Kindle | H15: Malachi Kindle | I15: Malachi Kindle | J15: =Master_Roster[[#This Row],[Simple Name]] -> Malachi Kindle | K15: Kindle, Malachi | L15: =IFERROR(VLOOKUP(Master_Roster[[#This Row],[Offical ID]],'Online Roster'!L$3:M$112,2,FALSE),"") -> DL | M15: {=IFERROR(_xlfn.IFS(OR(Master_Roster[[#This Row],[Position]]="OL",Master_Roster[[#This Row],[Position]]="DL"),"Bigs",OR(Master_Roster[[#This Row],[Position]]="ILB",Master_Roster[[#This Row],[Position]]="OLB",Master_Roster[[#This Row],[Position]]="TE",Master_Roster[[#This Row],[Position]]="QB",Master_Roster[[#This Row],[Position]]="RB",Master_Roster[[#This Row],[Position]]="FB"),"Mids",OR(Master_Roster[[#This Row],[Position]]="WR",Master_Roster[[#This Row],[Position]]="CB",Master_Roster[[#This Row],[Position]]="S"),"Skills",OR(Master_Roster[[#This Row],[Position]]="K",Master_Roster[[#This Row],[Position]]="P",Master_Roster[[#This Row],[Position]]="LS",),"Spec"),"")} -> Bigs | N15: =Master_Roster[[#This Row],[Offical ID]] -> Kindle_Malachi_25 | O15: Back-Up
A16: Active | B16: Brodie Tagaloa | C16: Brodie Tagaloa | D16: Tagaloa_Brodie_25 | E16: =CONCATENATE(Master_Roster[[#This Row],[Last Name]],", ",MID(Master_Roster[[#This Row],[First Name]],1,2)) -> Tagaloa, Br | F16: Brodie | G16: Tagaloa | H16: Brodie Tagaloa | I16: Brodie Tagaloa | J16: Brodie Tagaloa | K16: Tagaloa, Brodie | L16: =IFERROR(VLOOKUP(Master_Roster[[#This Row],[Offical ID]],'Online Roster'!L$3:M$112,2,FALSE),"") -> DL | M16: {=IFERROR(_xlfn.IFS(OR(Master_Roster[[#This Row],[Position]]="OL",Master_Roster[[#This Row],[Position]]="DL"),"Bigs",OR(Master_Roster[[#This Row],[Position]]="ILB",Master_Roster[[#This Row],[Position]]="OLB",Master_Roster[[#This Row],[Position]]="TE",Master_Roster[[#This Row],[Position]]="QB",Master_Roster[[#This Row],[Position]]="RB",Master_Roster[[#This Row],[Position]]="FB"),"Mids",OR(Master_Roster[[#This Row],[Position]]="WR",Master_Roster[[#This Row],[Position]]="CB",Master_Roster[[#This Row],[Position]]="S"),"Skills",OR(Master_Roster[[#This Row],[Position]]="K",Master_Roster[[#This Row],[Position]]="P",Master_Roster[[#This Row],[Position]]="LS",),"Spec"),"")} -> Bigs | N16: =Master_Roster[[#This Row],[Offical ID]] -> Tagaloa_Brodie_25 | O16: Back-Up
A17: Active | B17: Malik Tullis | C17: Malik Tullis | D17: Tullis_Malik_25 | E17: =CONCATENATE(Master_Roster[[#This Row],[Last Name]],", ",MID(Master_Roster[[#This Row],[First Name]],1,2)) -> Tullis, Ma | F17: Malik | G17: Tullis | H17: Malik Tullis | I17: Malik Tullis | J17: Malik Tullis | K17: Tullis, Malik | L17: =IFERROR(VLOOKUP(Master_Roster[[#This Row],[Offical ID]],'Online Roster'!L$3:M$112,2,FALSE),"") -> DL | M17: {=IFERROR(_xlfn.IFS(OR(Master_Roster[[#This Row],[Position]]="OL",Master_Roster[[#This Row],[Position]]="DL"),"Bigs",OR(Master_Roster[[#This Row],[Position]]="ILB",Master_Roster[[#This Row],[Position]]="OLB",Master_Roster[[#This Row],[Position]]="TE",Master_Roster[[#This Row],[Position]]="QB",Master_Roster[[#This Row],[Position]]="RB",Master_Roster[[#This Row],[Position]]="FB"),"Mids",OR(Master_Roster[[#This Row],[Position]]="WR",Master_Roster[[#This Row],[Position]]="CB",Master_Roster[[#This Row],[Position]]="S"),"Skills",OR(Master_Roster[[#This Row],[Position]]="K",Master_Roster[[#This Row],[Position]]="P",Master_Roster[[#This Row],[Position]]="LS",),"Spec"),"")} -> Bigs | N17: =Master_Roster[[#This Row],[Offical ID]] -> Tullis_Malik_25 | O17: Back-Up
A18: Active | B18: James Gillespie | C18: James Gillespie | D18: Gillespie_James_25 | E18: =CONCATENATE(Master_Roster[[#This Row],[Last Name]],", ",MID(Master_Roster[[#This Row],[First Name]],1,2)) -> Gillespie, Ja | F18: James | G18: Gillespie | H18: James Gillespie | I18: James Gillespie | J18: James Gillespie | K18: Gillespie, James | L18: =IFERROR(VLOOKUP(Master_Roster[[#This Row],[Offical ID]],'Online Roster'!L$3:M$112,2,FALSE),"") -> DL | M18: {=IFERROR(_xlfn.IFS(OR(Master_Roster[[#This Row],[Position]]="OL",Master_Roster[[#This Row],[Position]]="DL"),"Bigs",OR(Master_Roster[[#This Row],[Position]]="ILB",Master_Roster[[#This Row],[Position]]="OLB",Master_Roster[[#This Row],[Position]]="TE",Master_Roster[[#This Row],[Position]]="QB",Master_Roster[[#This Row],[Position]]="RB",Master_Roster[[#This Row],[Position]]="FB"),"Mids",OR(Master_Roster[[#This Row],[Position]]="WR",Master_Roster[[#This Row],[Position]]="CB",Master_Roster[[#This Row],[Position]]="S"),"Skills",OR(Master_Roster[[#This Row],[Position]]="K",Master_Roster[[#This Row],[Position]]="P",Master_Roster[[#This Row],[Position]]="LS",),"Spec"),"")} -> Bigs | N18: =Master_Roster[[#This Row],[Offical ID]] -> Gillespie_James_25 | O18: Rotation
A19: Active | B19: Syncere Massey | C19: Syncere Massey | D19: Massey_Syncere_25 | E19: =CONCATENATE(Master_Roster[[#This Row],[Last Name]],", ",MID(Master_Roster[[#This Row],[First Name]],1,2)) -> Massey, Sy | F19: Syncere | G19: Massey | H19: Syncere Massey | I19: Syncere Massey | J19: Syncere Massey | K19: Massey, Syncere | L19: =IFERROR(VLOOKUP(Master_Roster[[#This Row],[Offical ID]],'Online Roster'!L$3:M$112,2,FALSE),"") -> DL | M19: {=IFERROR(_xlfn.IFS(OR(Master_Roster[[#This Row],[Position]]="OL",Master_Roster[[#This Row],[Position]]="DL"),"Bigs",OR(Master_Roster[[#This Row],[Position]]="ILB",Master_Roster[[#This Row],[Position]]="OLB",Master_Roster[[#This Row],[Position]]="TE",Master_Roster[[#This Row],[Position]]="QB",Master_Roster[[#This Row],[Position]]="RB",Master_Roster[[#This Row],[Position]]="FB"),"Mids",OR(Master_Roster[[#This Row],[Position]]="WR",Master_Roster[[#This Row],[Position]]="CB",Master_Roster[[#This Row],[Position]]="S"),"Skills",OR(Master_Roster[[#This Row],[Position]]="K",Master_Roster[[#This Row],[Position]]="P",Master_Roster[[#This Row],[Position]]="LS",),"Spec"),"")} -> Bigs | N19: =Master_Roster[[#This Row],[Offical ID]] -> Massey_Syncere_25 | O19: Rotation
A20: Active | B20: Melvin Swindle II | C20: Melvin Swindle | D20: Swindle_Melvin_25 | E20: =CONCATENATE(Master_Roster[[#This Row],[Last Name]],", ",MID(Master_Roster[[#This Row],[First Name]],1,2)) -> Swindle, Me | F20: Melvin | G20: Swindle | H20: Melvin Swindle | I20: Melvin Swindle | J20: Melvin Swindle | K20: Swindle, Melvin | L20: =IFERROR(VLOOKUP(Master_Roster[[#This Row],[Offical ID]],'Online Roster'!L$3:M$112,2,FALSE),"") -> DL | M20: {=IFERROR(_xlfn.IFS(OR(Master_Roster[[#This Row],[Position]]="OL",Master_Roster[[#This Row],[Position]]="DL"),"Bigs",OR(Master_Roster[[#This Row],[Position]]="ILB",Master_Roster[[#This Row],[Position]]="OLB",Master_Roster[[#This Row],[Position]]="TE",Master_Roster[[#This Row],[Position]]="QB",Master_Roster[[#This Row],[Position]]="RB",Master_Roster[[#This Row],[Position]]="FB"),"Mids",OR(Master_Roster[[#This Row],[Position]]="WR",Master_Roster[[#This Row],[Position]]="CB",Master_Roster[[#This Row],[Position]]="S"),"Skills",OR(Master_Roster[[#This Row],[Position]]="K",Master_Roster[[#This Row],[Position]]="P",Master_Roster[[#This Row],[Position]]="LS",),"Spec"),"")} -> Bigs | N20: =Master_Roster[[#This Row],[Offical ID]] -> Swindle_Melvin_25 | O20: Starter
A21: Active | B21: Miles Bailey | C21: Miles Bailey | D21: Bailey_Miles_25 | E21: =CONCATENATE(Master_Roster[[#This Row],[Last Name]],", ",MID(Master_Roster[[#This Row],[First Name]],1,2)) -> Bailey, Mi | F21: Miles | G21: Bailey | H21: Miles Bailey | I21: Miles Bailey | J21: Miles Bailey | K21: Bailey, Miles | L21: =IFERROR(VLOOKUP(Master_Roster[[#This Row],[Offical ID]],'Online Roster'!L$3:M$112,2,FALSE),"") -> DL | M21: {=IFERROR(_xlfn.IFS(OR(Master_Roster[[#This Row],[Position]]="OL",Master_Roster[[#This Row],[Position]]="DL"),"Bigs",OR(Master_Roster[[#This Row],[Position]]="ILB",Master_Roster[[#This Row],[Position]]="OLB",Master_Roster[[#This Row],[Position]]="TE",Master_Roster[[#This Row],[Position]]="QB",Master_Roster[[#This Row],[Position]]="RB",Master_Roster[[#This Row],[Position]]="FB"),"Mids",OR(Master_Roster[[#This Row],[Position]]="WR",Master_Roster[[#This Row],[Position]]="CB",Master_Roster[[#This Row],[Position]]="S"),"Skills",OR(Master_Roster[[#This Row],[Position]]="K",Master_Roster[[#This Row],[Position]]="P",Master_Roster[[#This Row],[Position]]="LS",),"Spec"),"")} -> Bigs | N21: =Master_Roster[[#This Row],[Offical ID]] -> Bailey_Miles_25 | O21: Starter
A22: Active | B22: Jayland McGlothen | C22: Jayland McGlothen | D22: McGlothen_Jayland_25 | E22: =CONCATENATE(Master_Roster[[#This Row],[Last Name]],", ",MID(Master_Roster[[#This Row],[First Name]],1,2)) -> McGlothen, Ja | F22: Jayland | G22: McGlothen | H22: Jayland McGlothen | I22: Jayland McGlothen | J22: Jayland McGlothen | K22: McGlothen, Jayland | L22: =IFERROR(VLOOKUP(Master_Roster[[#This Row],[Offical ID]],'Online Roster'!L$3:M$112,2,FALSE),"") -> DL | M22: {=IFERROR(_xlfn.IFS(OR(Master_Roster[[#This Row],[Position]]="OL",Master_Roster[[#This Row],[Position]]="DL"),"Bigs",OR(Master_Roster[[#This Row],[Position]]="ILB",Master_Roster[[#This Row],[Position]]="OLB",Master_Roster[[#This Row],[Position]]="TE",Master_Roster[[#This Row],[Position]]="QB",Master_Roster[[#This Row],[Position]]="RB",Master_Roster[[#This Row],[Position]]="FB"),"Mids",OR(Master_Roster[[#This Row],[Position]]="WR",Master_Roster[[#This Row],[Position]]="CB",Master_Roster[[#This Row],[Position]]="S"),"Skills",OR(Master_Roster[[#This Row],[Position]]="K",Master_Roster[[#This Row],[Position]]="P",Master_Roster[[#This Row],[Position]]="LS",),"Spec"),"")} -> Bigs | N22: =Master_Roster[[#This Row],[Offical ID]] -> McGlothen_Jayland_25 | O22: Starter
A23: Active | B23: DeSean Watts | C23: DeSean Watts | D23: Watts_DeSean_25 | E23: =CONCATENATE(Master_Roster[[#This Row],[Last Name]],", ",MID(Master_Roster[[#This Row],[First Name]],1,2)) -> Watts, De | F23: DeSean | G23: Watts | H23: DeSean Watts | I23: DeSean Watts | J23: DeSean Watts | K23: Watts, Desean | L23: =IFERROR(VLOOKUP(Master_Roster[[#This Row],[Offical ID]],'Online Roster'!L$3:M$112,2,FALSE),"") -> DL | M23: {=IFERROR(_xlfn.IFS(OR(Master_Roster[[#This Row],[Position]]="OL",Master_Roster[[#This Row],[Position]]="DL"),"Bigs",OR(Master_Roster[[#This Row],[Position]]="ILB",Master_Roster[[#This Row],[Position]]="OLB",Master_Roster[[#This Row],[Position]]="TE",Master_Roster[[#This Row],[Position]]="QB",Master_Roster[[#This Row],[Position]]="RB",Master_Roster[[#This Row],[Position]]="FB"),"Mids",OR(Master_Roster[[#This Row],[Position]]="WR",Master_Roster[[#This Row],[Position]]="CB",Master_Roster[[#This Row],[Position]]="S"),"Skills",OR(Master_Roster[[#This Row],[Position]]="K",Master_Roster[[#This Row],[Position]]="P",Master_Roster[[#This Row],[Position]]="LS",),"Spec"),"")} -> Bigs | N23: =Master_Roster[[#This Row],[Offical ID]] -> Watts_DeSean_25 | O23: Starter
A24: Active | B24: Xavier Williams | C24: Xavier Williams | D24: Williams_Xavier_25 | E24: =CONCATENATE(Master_Roster[[#This Row],[Last Name]],", ",MID(Master_Roster[[#This Row],[First Name]],1,2)) -> Williams, Xa | F24: Xavier | G24: Williams | H24: Xavier Williams | I24: Xavier Williams | J24: Xavier Williams | K24: Williams, Xavier | L24: =IFERROR(VLOOKUP(Master_Roster[[#This Row],[Offical ID]],'Online Roster'!L$3:M$112,2,FALSE),"") -> DL | M24: {=IFERROR(_xlfn.IFS(OR(Master_Roster[[#This Row],[Position]]="OL",Master_Roster[[#This Row],[Position]]="DL"),"Bigs",OR(Master_Roster[[#This Row],[Position]]="ILB",Master_Roster[[#This Row],[Position]]="OLB",Master_Roster[[#This Row],[Position]]="TE",Master_Roster[[#This Row],[Position]]="QB",Master_Roster[[#This Row],[Position]]="RB",Master_Roster[[#This Row],[Position]]="FB"),"Mids",OR(Master_Roster[[#This Row],[Position]]="WR",Master_Roster[[#This Row],[Position]]="CB",Master_Roster[[#This Row],[Position]]="S"),"Skills",OR(Master_Roster[[#This Row],[Position]]="K",Master_Roster[[#This Row],[Position]]="P",Master_Roster[[#This Row],[Position]]="LS",),"Spec"),"")} -> Bigs | N24: =Master_Roster[[#This Row],[Offical ID]] -> Williams_Xavier_25 | O24: Starter
A25: Active | B25: Sammy Norris | C25: Sammy Norris | D25: Norris_Sammy_25 | E25: =CONCATENATE(Master_Roster[[#This Row],[Last Name]],", ",MID(Master_Roster[[#This Row],[First Name]],1,2)) -> Norris, Sa | F25: Sammy | G25: Norris | H25: Sammy Norris | I25: Sammy Norris | J25: Sammy Norris | K25: Norris, Sammy | L25: =IFERROR(VLOOKUP(Master_Roster[[#This Row],[Offical ID]],'Online Roster'!L$3:M$112,2,FALSE),"") -> FB | M25: {=IFERROR(_xlfn.IFS(OR(Master_Roster[[#This Row],[Position]]="OL",Master_Roster[[#This Row],[Position]]="DL"),"Bigs",OR(Master_Roster[[#This Row],[Position]]="ILB",Master_Roster[[#This Row],[Position]]="OLB",Master_Roster[[#This Row],[Position]]="TE",Master_Roster[[#This Row],[Position]]="QB",Master_Roster[[#This Row],[Position]]="RB",Master_Roster[[#This Row],[Position]]="FB"),"Mids",OR(Master_Roster[[#This Row],[Position]]="WR",Master_Roster[[#This Row],[Position]]="CB",Master_Roster[[#This Row],[Position]]="S"),"Skills",OR(Master_Roster[[#This Row],[Position]]="K",Master_Roster[[#This Row],[Position]]="P",Master_Roster[[#This Row],[Position]]="LS",),"Spec"),"")} -> Mids | N25: =Master_Roster[[#This Row],[Offical ID]] -> Norris_Sammy_25 | O25: Rotation
A26: Active | B26: Luke Slater | C26: Luke Slater | D26: Slater_Luke_25 | E26: =CONCATENATE(Master_Roster[[#This Row],[Last Name]],", ",MID(Master_Roster[[#This Row],[First Name]],1,2)) -> Slater, Lu | F26: Luke | G26: Slater | H26: Luke Slater | I26: Luke Slater | J26: Luke Slater | K26: Slater, Luke | L26: FB | M26: {=IFERROR(_xlfn.IFS(OR(Master_Roster[[#This Row],[Position]]="OL",Master_Roster[[#This Row],[Position]]="DL"),"Bigs",OR(Master_Roster[[#This Row],[Position]]="ILB",Master_Roster[[#This Row],[Position]]="OLB",Master_Roster[[#This Row],[Position]]="TE",Master_Roster[[#This Row],[Position]]="QB",Master_Roster[[#This Row],[Position]]="RB",Master_Roster[[#This Row],[Position]]="FB"),"Mids",OR(Master_Roster[[#This Row],[Position]]="WR",Master_Roster[[#This Row],[Position]]="CB",Master_Roster[[#This Row],[Position]]="S"),"Skills",OR(Master_Roster[[#This Row],[Position]]="K",Master_Roster[[#This Row],[Position]]="P",Master_Roster[[#This Row],[Position]]="LS",),"Spec"),"")} -> Mids | N26: =Master_Roster[[#This Row],[Offical ID]] -> Slater_Luke_25 | O26: Rotation
A27: Active | B27: Hunter Boeddeker | C27: Hunter Boeddeker | D27: Boeddeker_Hunter_25 | E27: =CONCATENATE(Master_Roster[[#This Row],[Last Name]],", ",MID(Master_Roster[[#This Row],[First Name]],1,2)) -> Boeddeker, Hu | F27: Hunter | G27: Boeddeker | H27: Hunter Boeddeker | I27: Hunter Boeddeker | J27: Hunter Boeddeker | K27: Boeddeker, Hunter | L27: ILB | M27: {=IFERROR(_xlfn.IFS(OR(Master_Roster[[#This Row],[Position]]="OL",Master_Roster[[#This Row],[Position]]="DL"),"Bigs",OR(Master_Roster[[#This Row],[Position]]="ILB",Master_Roster[[#This Row],[Position]]="OLB",Master_Roster[[#This Row],[Position]]="TE",Master_Roster[[#This Row],[Position]]="QB",Master_Roster[[#This Row],[Position]]="RB",Master_Roster[[#This Row],[Position]]="FB"),"Mids",OR(Master_Roster[[#This Row],[Position]]="WR",Master_Roster[[#This Row],[Position]]="CB",Master_Roster[[#This Row],[Position]]="S"),"Skills",OR(Master_Roster[[#This Row],[Position]]="K",Master_Roster[[#This Row],[Position]]="P",Master_Roster[[#This Row],[Position]]="LS",),"Spec"),"")} -> Mids | N27: =Master_Roster[[#This Row],[Offical ID]] -> Boeddeker_Hunter_25 | O27: Back-Up
A28: Active | B28: Jackson Cahoon | C28: Jackson Cahoon | D28: Cahoon_Jackson_25 | E28: =CONCATENATE(Master_Roster[[#This Row],[Last Name]],", ",MID(Master_Roster[[#This Row],[First Name]],1,2)) -> Cahoon, Ja | F28: Jackson | G28: Cahoon | H28: Jackson Cahoon | I28: Jackson Cahoon | J28: =Master_Roster[[#This Row],[Simple Name]] -> Jackson Cahoon | K28: Cahoon, Jackson | L28: =IFERROR(VLOOKUP(Master_Roster[[#This Row],[Offical ID]],'Online Roster'!L$3:M$112,2,FALSE),"") -> ILB | M28: {=IFERROR(_xlfn.IFS(OR(Master_Roster[[#This Row],[Position]]="OL",Master_Roster[[#This Row],[Position]]="DL"),"Bigs",OR(Master_Roster[[#This Row],[Position]]="ILB",Master_Roster[[#This Row],[Position]]="OLB",Master_Roster[[#This Row],[Position]]="TE",Master_Roster[[#This Row],[Position]]="QB",Master_Roster[[#This Row],[Position]]="RB",Master_Roster[[#This Row],[Position]]="FB"),"Mids",OR(Master_Roster[[#This Row],[Position]]="WR",Master_Roster[[#This Row],[Position]]="CB",Master_Roster[[#This Row],[Position]]="S"),"Skills",OR(Master_Roster[[#This Row],[Position]]="K",Master_Roster[[#This Row],[Position]]="P",Master_Roster[[#This Row],[Position]]="LS",),"Spec"),"")} -> Mids | N28: =Master_Roster[[#This Row],[Offical ID]] -> Cahoon_Jackson_25 | O28: Back-Up
A29: Active | B29: Mike Taylor | C29: Mike Taylor | D29: Taylor_Mike_25 | E29: =CONCATENATE(Master_Roster[[#This Row],[Last Name]],", ",MID(Master_Roster[[#This Row],[First Name]],1,2)) -> Taylor, Mi | F29: Mike | G29: Taylor | H29: Mike Taylor | I29: Mike Taylor | J29: =Master_Roster[[#This Row],[Simple Name]] -> Mike Taylor | K29: Taylor, Mike | L29: =IFERROR(VLOOKUP(Master_Roster[[#This Row],[Offical ID]],'Online Roster'!L$3:M$112,2,FALSE),"") -> ILB | M29: {=IFERROR(_xlfn.IFS(OR(Master_Roster[[#This Row],[Position]]="OL",Master_Roster[[#This Row],[Position]]="DL"),"Bigs",OR(Master_Roster[[#This Row],[Position]]="ILB",Master_Roster[[#This Row],[Position]]="OLB",Master_Roster[[#This Row],[Position]]="TE",Master_Roster[[#This Row],[Position]]="QB",Master_Roster[[#This Row],[Position]]="RB",Master_Roster[[#This Row],[Position]]="FB"),"Mids",OR(Master_Roster[[#This Row],[Position]]="WR",Master_Roster[[#This Row],[Position]]="CB",Master_Roster[[#This Row],[Position]]="S"),"Skills",OR(Master_Roster[[#This Row],[Position]]="K",Master_Roster[[#This Row],[Position]]="P",Master_Roster[[#This Row],[Position]]="LS",),"Spec"),"")} -> Mids | N29: =Master_Roster[[#This Row],[Offical ID]] -> Taylor_Mike_25 | O29: Back-Up
A30: Active | B30: Matthew Eskridge II | C30: Matthew Eskridge | D30: Eskridge_Matthew_25 | E30: =CONCATENATE(Master_Roster[[#This Row],[Last Name]],", ",MID(Master_Roster[[#This Row],[First Name]],1,2)) -> Eskridge, Ma | F30: Matthew | G30: Eskridge | H30: Matthew Eskridge | I30: Matthew Eskridge | J30: Matthew Eskridge | K30: Eskridge, Matthew | L30: =IFERROR(VLOOKUP(Master_Roster[[#This Row],[Offical ID]],'Online Roster'!L$3:M$112,2,FALSE),"") -> ILB | M30: {=IFERROR(_xlfn.IFS(OR(Master_Roster[[#This Row],[Position]]="OL",Master_Roster[[#This Row],[Position]]="DL"),"Bigs",OR(Master_Roster[[#This Row],[Position]]="ILB",Master_Roster[[#This Row],[Position]]="OLB",Master_Roster[[#This Row],[Position]]="TE",Master_Roster[[#This Row],[Position]]="QB",Master_Roster[[#This Row],[Position]]="RB",Master_Roster[[#This Row],[Position]]="FB"),"Mids",OR(Master_Roster[[#This Row],[Position]]="WR",Master_Roster[[#This Row],[Position]]="CB",Master_Roster[[#This Row],[Position]]="S"),"Skills",OR(Master_Roster[[#This Row],[Position]]="K",Master_Roster[[#This Row],[Position]]="P",Master_Roster[[#This Row],[Position]]="LS",),"Spec"),"")} -> Mids | N30: =Master_Roster[[#This Row],[Offical ID]] -> Eskridge_Matthew_25 | O30: Back-Up
A31: Active | B31: KJ Jefferson | C31: KJ Jefferson | D31: Jefferson_KJ_25 | E31: =CONCATENATE(Master_Roster[[#This Row],[Last Name]],", ",MID(Master_Roster[[#This Row],[First Name]],1,2)) -> Jefferson, KJ | F31: KJ | G31: Jefferson | H31: KJ Jefferson | I31: KJ Jefferson | J31: =Master_Roster[[#This Row],[Simple Name]] -> KJ Jefferson | K31: Jefferson, Karvon | L31: ILB | M31: Mids | N31: =Master_Roster[[#This Row],[Offical ID]] -> Jefferson_KJ_25 | O31: Back-Up
A32: Active | B32: Jekob Jones | C32: Jekob Jones | D32: Jones_Jekob_25 | E32: =CONCATENATE(Master_Roster[[#This Row],[Last Name]],", ",MID(Master_Roster[[#This Row],[First Name]],1,2)) -> Jones, Je | F32: Jekob | G32: Jones | H32: Jekob Jones | I32: Jekob Jones | J32: =Master_Roster[[#This Row],[Simple Name]] -> Jekob Jones | K32: Jones, Jekob | L32: =IFERROR(VLOOKUP(Master_Roster[[#This Row],[Offical ID]],'Online Roster'!L$3:M$112,2,FALSE),"") -> ILB | M32: {=IFERROR(_xlfn.IFS(OR(Master_Roster[[#This Row],[Position]]="OL",Master_Roster[[#This Row],[Position]]="DL"),"Bigs",OR(Master_Roster[[#This Row],[Position]]="ILB",Master_Roster[[#This Row],[Position]]="OLB",Master_Roster[[#This Row],[Position]]="TE",Master_Roster[[#This Row],[Position]]="QB",Master_Roster[[#This Row],[Position]]="RB",Master_Roster[[#This Row],[Position]]="FB"),"Mids",OR(Master_Roster[[#This Row],[Position]]="WR",Master_Roster[[#This Row],[Position]]="CB",Master_Roster[[#This Row],[Position]]="S"),"Skills",OR(Master_Roster[[#This Row],[Position]]="K",Master_Roster[[#This Row],[Position]]="P",Master_Roster[[#This Row],[Position]]="LS",),"Spec"),"")} -> Mids | N32: =Master_Roster[[#This Row],[Offical ID]] -> Jones_Jekob_25 | O32: Back-Up
A33: Active | B33: Alex Rocha | C33: Alex Rocha | D33: Rocha_Alex_25 | E33: =CONCATENATE(Master_Roster[[#This Row],[Last Name]],", ",MID(Master_Roster[[#This Row],[First Name]],1,2)) -> Rocha, Al | F33: Alex | G33: Rocha | H33: Alex Rocha | I33: Alex Rocha | J33: Alex Rocha | K33: Rocha, Alex | L33: =IFERROR(VLOOKUP(Master_Roster[[#This Row],[Offical ID]],'Online Roster'!L$3:M$112,2,FALSE),"") -> ILB | M33: {=IFERROR(_xlfn.IFS(OR(Master_Roster[[#This Row],[Position]]="OL",Master_Roster[[#This Row],[Position]]="DL"),"Bigs",OR(Master_Roster[[#This Row],[Position]]="ILB",Master_Roster[[#This Row],[Position]]="OLB",Master_Roster[[#This Row],[Position]]="TE",Master_Roster[[#This Row],[Position]]="QB",Master_Roster[[#This Row],[Position]]="RB",Master_Roster[[#This Row],[Position]]="FB"),"Mids",OR(Master_Roster[[#This Row],[Position]]="WR",Master_Roster[[#This Row],[Position]]="CB",Master_Roster[[#This Row],[Position]]="S"),"Skills",OR(Master_Roster[[#This Row],[Position]]="K",Master_Roster[[#This Row],[Position]]="P",Master_Roster[[#This Row],[Position]]="LS",),"Spec"),"")} -> Mids | N33: =Master_Roster[[#This Row],[Offical ID]] -> Rocha_Alex_25 | O33: Back-Up
A34: Active | B34: Max Susini | C34: Max Susini | D34: Susini_Max_25 | E34: =CONCATENATE(Master_Roster[[#This Row],[Last Name]],", ",MID(Master_Roster[[#This Row],[First Name]],1,2)) -> Susini, Ma | F34: Max | G34: Susini | H34: Max Susini | I34: Max Susini | J34: Max Susini | K34: =CONCATENATE(Master_Roster[[#This Row],[Last Name]],", ",Master_Roster[[#This Row],[First Name]]) -> Susini, Max | L34: ILB | M34: Mids | N34: =Master_Roster[[#This Row],[Offical ID]] -> Susini_Max_25 | O34: Back-Up
A35: Active | B35: Oscar Moore | C35: Oscar Moore | D35: Moore_Oscar_25 | E35: =CONCATENATE(Master_Roster[[#This Row],[Last Name]],", ",MID(Master_Roster[[#This Row],[First Name]],1,2)) -> Moore, Os | F35: Oscar | G35: Moore | H35: Oscar Moore | I35: Oscar Moore | J35: Oscar Moore | K35: Moore, Oscar | L35: ILB | M35: {=IFERROR(_xlfn.IFS(OR(Master_Roster[[#This Row],[Position]]="OL",Master_Roster[[#This Row],[Position]]="DL"),"Bigs",OR(Master_Roster[[#This Row],[Position]]="ILB",Master_Roster[[#This Row],[Position]]="OLB",Master_Roster[[#This Row],[Position]]="TE",Master_Roster[[#This Row],[Position]]="QB",Master_Roster[[#This Row],[Position]]="RB",Master_Roster[[#This Row],[Position]]="FB"),"Mids",OR(Master_Roster[[#This Row],[Position]]="WR",Master_Roster[[#This Row],[Position]]="CB",Master_Roster[[#This Row],[Position]]="S"),"Skills",OR(Master_Roster[[#This Row],[Position]]="K",Master_Roster[[#This Row],[Position]]="P",Master_Roster[[#This Row],[Position]]="LS",),"Spec"),"")} -> Mids | N35: =Master_Roster[[#This Row],[Offical ID]] -> Moore_Oscar_25 | O35: Rotation
A36: Active | B36: Diego Davis | C36: Diego Davis | D36: Davis_Diego_25 | E36: =CONCATENATE(Master_Roster[[#This Row],[Last Name]],", ",MID(Master_Roster[[#This Row],[First Name]],1,2)) -> Davis, Di | F36: Diego | G36: Davis | H36: Diego Davis | I36: Diego Davis | J36: Diego Davis | K36: Davis, Diego | L36: =IFERROR(VLOOKUP(Master_Roster[[#This Row],[Offical ID]],'Online Roster'!L$3:M$112,2,FALSE),"") -> ILB | M36: {=IFERROR(_xlfn.IFS(OR(Master_Roster[[#This Row],[Position]]="OL",Master_Roster[[#This Row],[Position]]="DL"),"Bigs",OR(Master_Roster[[#This Row],[Position]]="ILB",Master_Roster[[#This Row],[Position]]="OLB",Master_Roster[[#This Row],[Position]]="TE",Master_Roster[[#This Row],[Position]]="QB",Master_Roster[[#This Row],[Position]]="RB",Master_Roster[[#This Row],[Position]]="FB"),"Mids",OR(Master_Roster[[#This Row],[Position]]="WR",Master_Roster[[#This Row],[Position]]="CB",Master_Roster[[#This Row],[Position]]="S"),"Skills",OR(Master_Roster[[#This Row],[Position]]="K",Master_Roster[[#This Row],[Position]]="P",Master_Roster[[#This Row],[Position]]="LS",),"Spec"),"")} -> Mids | N36: =Master_Roster[[#This Row],[Offical ID]] -> Davis_Diego_25 | O36: Starter
A37: Active | B37: Derek Houston | C37: Derek Houston | D37: Houston_Derek_25 | E37: =CONCATENATE(Master_Roster[[#This Row],[Last Name]],", ",MID(Master_Roster[[#This Row],[First Name]],1,2)) -> Houston, De | F37: Derek | G37: Houston | H37: Derek Houston | I37: Derek Houston | J37: Derek Houston | K37: Houston, Derek | L37: =IFERROR(VLOOKUP(Master_Roster[[#This Row],[Offical ID]],'Online Roster'!L$3:M$112,2,FALSE),"") -> ILB | M37: {=IFERROR(_xlfn.IFS(OR(Master_Roster[[#This Row],[Position]]="OL",Master_Roster[[#This Row],[Position]]="DL"),"Bigs",OR(Master_Roster[[#This Row],[Position]]="ILB",Master_Roster[[#This Row],[Position]]="OLB",Master_Roster[[#This Row],[Position]]="TE",Master_Roster[[#This Row],[Position]]="QB",Master_Roster[[#This Row],[Position]]="RB",Master_Roster[[#This Row],[Position]]="FB"),"Mids",OR(Master_Roster[[#This Row],[Position]]="WR",Master_Roster[[#This Row],[Position]]="CB",Master_Roster[[#This Row],[Position]]="S"),"Skills",OR(Master_Roster[[#This Row],[Position]]="K",Master_Roster[[#This Row],[Position]]="P",Master_Roster[[#This Row],[Position]]="LS",),"Spec"),"")} -> Mids | N37: =Master_Roster[[#This Row],[Offical ID]] -> Houston_Derek_25 | O37: Starter
A38: Active | B38: Joseph Firebaugh | C38: Joseph Firebaugh | D38: Firebaugh_Joseph_25 | E38: =CONCATENATE(Master_Roster[[#This Row],[Last Name]],", ",MID(Master_Roster[[#This Row],[First Name]],1,2)) -> Firebaugh, Jo | F38: Joseph | G38: Firebaugh | H38: Joseph Firebaugh | I38: Joseph Firebaugh | J38: Joseph Firebaugh | K38: Firebaugh, Joseph | L38: =IFERROR(VLOOKUP(Master_Roster[[#This Row],[Offical ID]],'Online Roster'!L$3:M$112,2,FALSE),"") -> K | M38: {=IFERROR(_xlfn.IFS(OR(Master_Roster[[#This Row],[Position]]="OL",Master_Roster[[#This Row],[Position]]="DL"),"Bigs",OR(Master_Roster[[#This Row],[Position]]="ILB",Master_Roster[[#This Row],[Position]]="OLB",Master_Roster[[#This Row],[Position]]="TE",Master_Roster[[#This Row],[Position]]="QB",Master_Roster[[#This Row],[Position]]="RB",Master_Roster[[#This Row],[Position]]="FB"),"Mids",OR(Master_Roster[[#This Row],[Position]]="WR",Master_Roster[[#This Row],[Position]]="CB",Master_Roster[[#This Row],[Position]]="S"),"Skills",OR(Master_Roster[[#This Row],[Position]]="K",Master_Roster[[#This Row],[Position]]="P",Master_Roster[[#This Row],[Position]]="LS",),"Spec"),"")} -> Spec | N38: =Master_Roster[[#This Row],[Offical ID]] -> Firebaugh_Joseph_25 | O38: Back-Up
A39: Active | B39: Grant Meadors | C39: Grant Meadors | D39: Meadors_Grant_25 | E39: =CONCATENATE(Master_Roster[[#This Row],[Last Name]],", ",MID(Master_Roster[[#This Row],[First Name]],1,2)) -> Meadors, Gr | F39: Grant | G39: Meadors | H39: Grant Meadors | I39: Grant Meadors | J39: Grant Meadors | K39: Meadors, Grant | L39: =IFERROR(VLOOKUP(Master_Roster[[#This Row],[Offical ID]],'Online Roster'!L$3:M$112,2,FALSE),"") -> K | M39: {=IFERROR(_xlfn.IFS(OR(Master_Roster[[#This Row],[Position]]="OL",Master_Roster[[#This Row],[Position]]="DL"),"Bigs",OR(Master_Roster[[#This Row],[Position]]="ILB",Master_Roster[[#This Row],[Position]]="OLB",Master_Roster[[#This Row],[Position]]="TE",Master_Roster[[#This Row],[Position]]="QB",Master_Roster[[#This Row],[Position]]="RB",Master_Roster[[#This Row],[Position]]="FB"),"Mids",OR(Master_Roster[[#This Row],[Position]]="WR",Master_Roster[[#This Row],[Position]]="CB",Master_Roster[[#This Row],[Position]]="S"),"Skills",OR(Master_Roster[[#This Row],[Position]]="K",Master_Roster[[#This Row],[Position]]="P",Master_Roster[[#This Row],[Position]]="LS",),"Spec"),"")} -> Spec | N39: =Master_Roster[[#This Row],[Offical ID]] -> Meadors_Grant_25 | O39: Back-Up
A40: Active | B40: Hamish Adams | C40: Hamish Adams | D40: Adams_Hamish_25 | E40: =CONCATENATE(Master_Roster[[#This Row],[Last Name]],", ",MID(Master_Roster[[#This Row],[First Name]],1,2)) -> Adams, Ha | F40: Hamish | G40: Adams | H40: Hamish Adam’s | I40: Hamish Adams | J40: Hamish Adams | K40: =CONCATENATE(Master_Roster[[#This Row],[Last Name]],", ",Master_Roster[[#This Row],[First Name]]) -> Adams, Hamish | L40: K | M40: {=IFERROR(_xlfn.IFS(OR(Master_Roster[[#This Row],[Position]]="OL",Master_Roster[[#This Row],[Position]]="DL"),"Bigs",OR(Master_Roster[[#This Row],[Position]]="ILB",Master_Roster[[#This Row],[Position]]="OLB",Master_Roster[[#This Row],[Position]]="TE",Master_Roster[[#This Row],[Position]]="QB",Master_Roster[[#This Row],[Position]]="RB",Master_Roster[[#This Row],[Position]]="FB"),"Mids",OR(Master_Roster[[#This Row],[Position]]="WR",Master_Roster[[#This Row],[Position]]="CB",Master_Roster[[#This Row],[Position]]="S"),"Skills",OR(Master_Roster[[#This Row],[Position]]="K",Master_Roster[[#This Row],[Position]]="P",Master_Roster[[#This Row],[Position]]="LS",),"Spec"),"")} -> Spec | N40: =Master_Roster[[#This Row],[Offical ID]] -> Adams_Hamish_25 | O40: Back-Up
...

Sheet Sheet4
A1: Team | B1: Active
A3: Row Labels | B3: Count of Position
A4: CB | B4: 11 | E4: CB | F4: 11 | G4: L
A5: DL | B5: 11 | E5: DL | F5: 11 | G5: XXXL
A6: FB | B6: 2 | E6: FB | F6: 2 | G6: XXL
A7: ILB | B7: 11 | E7: ILB | F7: 11 | G7: XL
A8: K | B8: 3 | E8: K | F8: 3
A9: LS | B9: 2 | E9: LS | F9: 2
A10: OL | B10: 18 | E10: OL | F10: 18 | G10: XXXL
A11: OLB | B11: 7 | E11: OLB | F11: 7 | G11: XXL
A12: P | B12: 2 | E12: P | F12: 2
A13: QB | B13: 5 | E13: QB | F13: 5 | G13: L
A14: RB | B14: 8 | E14: RB | F14: 8 | G14: L
A15: S | B15: 9 | E15: S | F15: 9 | G15: L
A16: TE | B16: 5 | E16: TE | F16: 5 | G16: XL
A17: WR | B17: 16 | E17: WR | F17: 16 | G17: L
A18: Grand Total | B18: 110 | J18: Size | K18: Count
G19: {=_xlfn.UNIQUE(G4:G17)} -> L | H19: =SUMIFS(F$4:F$17,G$4:G$17,G19) -> 49 | J19: 4XL | K19: 15
G20: XXXL | H20: =SUMIFS(F$4:F$17,G$4:G$17,G20) -> 29 | J20: 3XL | K20: 15
G21: XXL | H21: =SUMIFS(F$4:F$17,G$4:G$17,G21) -> 9 | J21: 2XL | K21: 10
G22: XL | H22: =SUMIFS(F$4:F$17,G$4:G$17,G22) -> 16 | J22: XL | K22: 15
G23: 0 | J23: L | K23: 50
K25: =SUM(K19:K23) -> 105

Sheet Sheet1
A1: Jordan Anderson
A2: Tim Conerly
A3: Damien McDaniel
A4: Gavin Nelson
A5: Koa Akui
A6: Kaleb Higgins
A7: Jamar Curtis
A8: Rodney Hammond
A9: Savion Red
A10: Jaden Rashada
A11: Dylan Hampsten
A12: Josh Cashiola
... A26: Jayland McGlothen

Sheet Groups 721
A1: Name | B1: Position | C1: Position Class | D1: Tues 7/22 Group | E1: Starting Station | G1: Name | H1: Position | I1: Position Class | J1: Tues 7/22 Group | K1: Starting Station
A2: Dean Abdullah | B2: OL | C2: Bigs | D2: 1 | E2: Chains With Coach Eli | G2: Jaxon Moore | H2: OL | I2: Bigs | J2: 3 | K2: Build Ups With Coach O'Mary
A3: Miles Bailey | B3: DL | C3: Bigs | D3: 1 | E3: Chains With Coach Eli | G3: Elijah Ortiz | H3: OL | I3: Bigs | J3: 3 | K3: Build Ups With Coach O'Mary
A4: James Gillespie | B4: DL | C4: Bigs | D4: 1 | E4: Chains With Coach Eli | G4: Kenndel Riley | H4: OL | I4: Bigs | J4: 3 | K4: Build Ups With Coach O'Mary
A5: Cade Gretlein | B5: OL | C5: Bigs | D5: 1 | E5: Chains With Coach Eli | G5: Kris Ross | H5: DL | I5: Bigs | J5: 3 | K5: Build Ups With Coach O'Mary
A6: Dylan Hampsten | B6: DL | C6: Bigs | D6: 1 | E6: Chains With Coach Eli | G6: DeAnthony Sheffield | H6: OL | I6: Bigs | J6: 3 | K6: Build Ups With Coach O'Mary
A7: Sawyer Hays | B7: OL | C7: Bigs | D7: 1 | E7: Chains With Coach Eli | G7: Luke Slater | H7: OL | I7: Bigs | J7: 3 | K7: Build Ups With Coach O'Mary
A8: Jordan Herman | B8: OL | C8: Bigs | D8: 1 | E8: Chains With Coach Eli | G8: Jose Soto | H8: OL | I8: Bigs | J8: 3 | K8: Build Ups With Coach O'Mary
A9: Jordan Jefferson | B9: DL | C9: Bigs | D9: 1 | E9: Chains With Coach Eli | G9: Brandon Sousa | H9: OL | I9: Bigs | J9: 3 | K9: Build Ups With Coach O'Mary
A10: Sam Adams II | B10: RB | C10: Mids | D10: 1 | E10: Chains With Coach Eli | G10: Jekob Jones | H10: ILB | I10: Mids | J10: 3 | K10: Build Ups With Coach O'Mary
A11: Davis Ambuehl | B11: TE | C11: Mids | D11: 1 | E11: Chains With Coach Eli | G11: Jamar Malone | H11: QB | I11: Mids | J11: 3 | K11: Build Ups With Coach O'Mary
A12: Hunter Boeddeker | B12: ILB | C12: Mids | D12: 1 | E12: Chains With Coach Eli | G12: Micah Mosley | H12: OLB | I12: Mids | J12: 3 | K12: Build Ups With Coach O'Mary
A13: Curron Borders | B13: RB | C13: Mids | D13: 1 | E13: Chains With Coach Eli | G13: Gavin Nelson | H13: TE | I13: Mids | J13: 3 | K13: Build Ups With Coach O'Mary
... A56: Damien McDaniel | B56: WR | C56: Skills | D56: 2 | E56: Broad Jump With Coach Conner | G56: Mike Melanson | H56: P | I56: Spec | J56: 4 | K56: Vertec Test With Coach Shade and Shanahan
A57: Jaxon Moore | B57: OL | C57: Bigs | D57: 3 | E57: Build Ups With Coach O'Mary
A58: Elijah Ortiz | B58: OL | C58: Bigs | D58: 3 | E58: Build Ups With Coach O'Mary
A59: Kenndel Riley | B59: OL | C59: Bigs | D59: 3 | E59: Build Ups With Coach O'Mary
A60: Kris Ross | B60: DL | C60: Bigs | D60: 3 | E60: Build Ups With Coach O'Mary
A61: DeAnthony Sheffield | B61: OL | C61: Bigs | D61: 3 | E61: Build Ups With Coach O'Mary
A62: Luke Slater | B62: OL | C62: Bigs | D62: 3 | E62: Build Ups With Coach O'Mary
A63: Jose Soto | B63: OL | C63: Bigs | D63: 3 | E63: Build Ups With Coach O'Mary
A64: Brandon Sousa | B64: OL | C64: Bigs | D64: 3 | E64: Build Ups With Coach O'Mary
A65: Jekob Jones | B65: ILB | C65: Mids | D65: 3 | E65: Build Ups With Coach O'Mary
A66: Jamar Malone | B66: QB | C66: Mids | D66: 3 | E66: Build Ups With Coach O'Mary
A67: Micah Mosley | B67: OLB | C67: Mids | D67: 3 | E67: Build Ups With Coach O'Mary
A68: Gavin Nelson | B68: TE | C68: Mids | D68: 3 | E68: Build Ups With Coach O'Mary
... A111: Mike Melanson | B111: P | C111: Spec | D111: 4 | E111: Vertec Test With Coach Shade and Shanahan
C115: {=_xlfn.UNIQUE(Table3[Position Class])} -> Bigs | D115: =COUNTIF(Table3[Position Class],C115) -> 32 | E115: =ROUNDUP(D115/4,0) -> 8
C116: Mids | D116: =COUNTIF(Table3[Position Class],C116) -> 37 | E116: =ROUNDUP(D116/4,0) -> 10
C117: Skills | D117: =COUNTIF(Table3[Position Class],C117) -> 35 | E117: =ROUNDUP(D117/4,0) -> 9
C118: Spec | D118: =COUNTIF(Table3[Position Class],C118) -> 6 | E118: =ROUNDUP(D118/4,0) -> 2
C121: Group | D121: Total | E121: Bigs | F121: Mids | G121: Skills
C122: 1 | D122: =COUNTIF(Table3[Tues 7/22 Group],C122) -> 28 | E122: =COUNTIFS(Table3[Tues 7/22 Group],$C122,Table3[Position Class],E$121) -> 8 | F122: =COUNTIFS(Table3[Tues 7/22 Group],$C122,Table3[Position Class],F$121) -> 11 | G122: =COUNTIFS(Table3[Tues 7/22 Group],$C122,Table3[Position Class],G$121) -> 9
C123: 2 | D123: =COUNTIF(Table3[Tues 7/22 Group],C123) -> 27 | E123: =COUNTIFS(Table3[Tues 7/22 Group],$C123,Table3[Position Class],E$121) -> 8 | F123: =COUNTIFS(Table3[Tues 7/22 Group],$C123,Table3[Position Class],F$121) -> 10 | G123: =COUNTIFS(Table3[Tues 7/22 Group],$C123,Table3[Position Class],G$121) -> 9
C124: 3 | D124: =COUNTIF(Table3[Tues 7/22 Group],C124) -> 27 | E124: =COUNTIFS(Table3[Tues 7/22 Group],$C124,Table3[Position Class],E$121) -> 8 | F124: =COUNTIFS(Table3[Tues 7/22 Group],$C124,Table3[Position Class],F$121) -> 10 | G124: =COUNTIFS(Table3[Tues 7/22 Group],$C124,Table3[Position Class],G$121) -> 9
C125: 4 | D125: =COUNTIF(Table3[Tues 7/22 Group],C125) -> 28 | E125: =COUNTIFS(Table3[Tues 7/22 Group],$C125,Table3[Position Class],E$121) -> 8 | F125: =COUNTIFS(Table3[Tues 7/22 Group],$C125,Table3[Position Class],F$121) -> 6 | G125: =COUNTIFS(Table3[Tues 7/22 Group],$C125,Table3[Position Class],G$121) -> 8

Sheet Vendors
A1: VALD | C1: Kinexon | E1: Perch
A2: Vald Name | B2: Vald_Roster Count | C2: Kinexon | D2: Kinexon_Roster_Count | E2: Perch Name | F2: Perch_Roster Count
A3: Adam Johnston | B3: =IF(COUNTIF('Online Roster'!$B$3:$B$111,Vendors!A3)=0,COUNTIF('Online Roster'!$K$3:$K$111,Vendors!A3),COUNTIF('Online Roster'!$B$3:$B$111,Vendors!A3)) -> 1 | C3: Adam Johnston | D3: =IF(COUNTIF('Online Roster'!$B$3:$B$111,Vendors!C3)=0,COUNTIF('Online Roster'!$K$3:$K$111,Vendors!C3),COUNTIF('Online Roster'!$B$3:$B$111,Vendors!C3)) -> 1
A4: Adam Taylor | B4: =IF(COUNTIF('Online Roster'!$B$3:$B$111,Vendors!A4)=0,COUNTIF('Online Roster'!$K$3:$K$111,Vendors!A4),COUNTIF('Online Roster'!$B$3:$B$111,Vendors!A4)) -> 1 | C4: Adam Taylor | D4: =IF(COUNTIF('Online Roster'!$B$3:$B$111,Vendors!C4)=0,COUNTIF('Online Roster'!$K$3:$K$111,Vendors!C4),COUNTIF('Online Roster'!$B$3:$B$111,Vendors!C4)) -> 1
A5: Aidan Meek | B5: =IF(COUNTIF('Online Roster'!$B$3:$B$111,Vendors!A5)=0,COUNTIF('Online Roster'!$K$3:$K$111,Vendors!A5),COUNTIF('Online Roster'!$B$3:$B$111,Vendors!A5)) -> 1 | C5: Aidan Meek | D5: =IF(COUNTIF('Online Roster'!$B$3:$B$111,Vendors!C5)=0,COUNTIF('Online Roster'!$K$3:$K$111,Vendors!C5),COUNTIF('Online Roster'!$B$3:$B$111,Vendors!C5)) -> 1
A6: Ajon Bryant | B6: =IF(COUNTIF('Online Roster'!$B$3:$B$111,Vendors!A6)=0,COUNTIF('Online Roster'!$K$3:$K$111,Vendors!A6),COUNTIF('Online Roster'!$B$3:$B$111,Vendors!A6)) -> 1 | C6: Ajon Bryant | D6: =IF(COUNTIF('Online Roster'!$B$3:$B$111,Vendors!C6)=0,COUNTIF('Online Roster'!$K$3:$K$111,Vendors!C6),COUNTIF('Online Roster'!$B$3:$B$111,Vendors!C6)) -> 1
A7: Alex Rocha | B7: =IF(COUNTIF('Online Roster'!$B$3:$B$111,Vendors!A7)=0,COUNTIF('Online Roster'!$K$3:$K$111,Vendors!A7),COUNTIF('Online Roster'!$B$3:$B$111,Vendors!A7)) -> 1 | C7: Alex Rocha | D7: =IF(COUNTIF('Online Roster'!$B$3:$B$111,Vendors!C7)=0,COUNTIF('Online Roster'!$K$3:$K$111,Vendors!C7),COUNTIF('Online Roster'!$B$3:$B$111,Vendors!C7)) -> 1
A8: Anta'Veon McKenzie | B8: =IF(COUNTIF('Online Roster'!$B$3:$B$111,Vendors!A8)=0,COUNTIF('Online Roster'!$K$3:$K$111,Vendors!A8),COUNTIF('Online Roster'!$B$3:$B$111,Vendors!A8)) -> 1 | C8: Anta'Veon McKenzie | D8: =IF(COUNTIF('Online Roster'!$B$3:$B$111,Vendors!C8)=0,COUNTIF('Online Roster'!$K$3:$K$111,Vendors!C8),COUNTIF('Online Roster'!$B$3:$B$111,Vendors!C8)) -> 1
A9: Bear Tenney | B9: =IF(COUNTIF('Online Roster'!$B$3:$B$111,Vendors!A9)=0,COUNTIF('Online Roster'!$K$3:$K$111,Vendors!A9),COUNTIF('Online Roster'!$B$3:$B$111,Vendors!A9)) -> 1 | C9: Bear Tenney | D9: =IF(COUNTIF('Online Roster'!$B$3:$B$111,Vendors!C9)=0,COUNTIF('Online Roster'!$K$3:$K$111,Vendors!C9),COUNTIF('Online Roster'!$B$3:$B$111,Vendors!C9)) -> 1
A10: Brandon Sousa | B10: =IF(COUNTIF('Online Roster'!$B$3:$B$111,Vendors!A10)=0,COUNTIF('Online Roster'!$K$3:$K$111,Vendors!A10),COUNTIF('Online Roster'!$B$3:$B$111,Vendors!A10)) -> 1 | C10: Brandon Sousa | D10: =IF(COUNTIF('Online Roster'!$B$3:$B$111,Vendors!C10)=0,COUNTIF('Online Roster'!$K$3:$K$111,Vendors!C10),COUNTIF('Online Roster'!$B$3:$B$111,Vendors!C10)) -> 1
A11: Brennon Scott | B11: =IF(COUNTIF('Online Roster'!$B$3:$B$111,Vendors!A11)=0,COUNTIF('Online Roster'!$K$3:$K$111,Vendors!A11),COUNTIF('Online Roster'!$B$3:$B$111,Vendors!A11)) -> 1 | C11: Brennon Scott | D11: =IF(COUNTIF('Online Roster'!$B$3:$B$111,Vendors!C11)=0,COUNTIF('Online Roster'!$K$3:$K$111,Vendors!C11),COUNTIF('Online Roster'!$B$3:$B$111,Vendors!C11)) -> 1
A12: Brodie Tagaloa | B12: =IF(COUNTIF('Online Roster'!$B$3:$B$111,Vendors!A12)=0,COUNTIF('Online Roster'!$K$3:$K$111,Vendors!A12),COUNTIF('Online Roster'!$B$3:$B$111,Vendors!A12)) -> 1 | C12: Brodie Tagaloa | D12: =IF(COUNTIF('Online Roster'!$B$3:$B$111,Vendors!C12)=0,COUNTIF('Online Roster'!$K$3:$K$111,Vendors!C12),COUNTIF('Online Roster'!$B$3:$B$111,Vendors!C12)) -> 1
A13: Bryson Summers | B13: =IF(COUNTIF('Online Roster'!$B$3:$B$111,Vendors!A13)=0,COUNTIF('Online Roster'!$K$3:$K$111,Vendors!A13),COUNTIF('Online Roster'!$B$3:$B$111,Vendors!A13)) -> 1 | C13: Bryson Summers | D13: =IF(COUNTIF('Online Roster'!$B$3:$B$111,Vendors!C13)=0,COUNTIF('Online Roster'!$K$3:$K$111,Vendors!C13),COUNTIF('Online Roster'!$B$3:$B$111,Vendors!C13)) -> 1
A14: Cade Gretlein | B14: =IF(COUNTIF('Online Roster'!$B$3:$B$111,Vendors!A14)=0,COUNTIF('Online Roster'!$K$3:$K$111,Vendors!A14),COUNTIF('Online Roster'!$B$3:$B$111,Vendors!A14)) -> 1 | C14: Cade Gretlein | D14: =IF(COUNTIF('Online Roster'!$B$3:$B$111,Vendors!C14)=0,COUNTIF('Online Roster'!$K$3:$K$111,Vendors!C14),COUNTIF('Online Roster'!$B$3:$B$111,Vendors!C14)) -> 1
... A112: Mike Melanson | B112: =IF(COUNTIF('Online Roster'!$B$3:$B$111,Vendors!A112)=0,COUNTIF('Online Roster'!$K$3:$K$111,Vendors!A112),COUNTIF('Online Roster'!$B$3:$B$111,Vendors!A112)) -> 1 | C112: Mike Melanson | D112: =IF(COUNTIF('Online Roster'!$B$3:$B$111,Vendors!C112)=0,COUNTIF('Online Roster'!$K$3:$K$111,Vendors!C112),COUNTIF('Online Roster'!$B$3:$B$111,Vendors!C112)) -> 1
C113: Michael Johnson

Sheet Online Roster
A1: 2025 Football Roster
A2: No. | B2: Name | C2: Pos. | D2: Ht. | E2: Wt. | F2: Yr. | G2: Exp. | H2: Hometown | I2: High School | J2: Previous School | K2: Simple Name | L2: Offical Id | M2: Column1 | N2: Year
A3: 13 | B3: Ernest Campbell | C3: WR | D3: 45786 | E3: 145 | F3: R-Fr. | G3: TR | H3: Refugio, Texas | I3: Refugio HS | J3: Texas A&M | K3: {=_xlfn.LET( _xlpm.name, TRIM(B3), _xlpm.nameClean, SUBSTITUTE(SUBSTITUTE(_xlpm.name, ", Jr.", ""), " III", ""), _xlpm.parts, _xlfn.TEXTSPLIT(_xlpm.nameClean, " "), _xlpm.count, COUNTA(_xlpm.parts), _xlpm.first, INDEX(_xlpm.parts, 1), _xlpm.last, INDEX(_xlpm.parts, _xlpm.count), _xlpm.first & " " & _xlpm.last )} -> Ernest Campbell | L3: {=_xlfn.LET( _xlpm.name, TRIM(B3), _xlpm.nameClean, SUBSTITUTE(SUBSTITUTE(_xlpm.name, ", Jr.", ""), " III", ""), _xlpm.parts, _xlfn.TEXTSPLIT(_xlpm.nameClean, " "), _xlpm.count, COUNTA(_xlpm.parts), _xlpm.first, INDEX(_xlpm.parts, 1), _xlpm.last, INDEX(_xlpm.parts, _xlpm.count), _xlpm.result, _xlpm.last & "_" & _xlpm.first & "_25", _xlpm.result )} -> Campbell_Ernest_25 | M3: WR | N3: =Table5[[#This Row],[Yr.]] -> R-Fr.
A4: 8 | B4: Tim Conerly | C4: WR | D4: 45786 | E4: 157 | F4: Sr. | G4: TR | H4: New Orleans, La. | I4: Wright Charter HS | J4: UNLV | K4: {=_xlfn.LET( _xlpm.name, TRIM(B4), _xlpm.nameClean, SUBSTITUTE(SUBSTITUTE(_xlpm.name, ", Jr.", ""), " III", ""), _xlpm.parts, _xlfn.TEXTSPLIT(_xlpm.nameClean, " "), _xlpm.count, COUNTA(_xlpm.parts), _xlpm.first, INDEX(_xlpm.parts, 1), _xlpm.last, INDEX(_xlpm.parts, _xlpm.count), _xlpm.first & " " & _xlpm.last )} -> Tim Conerly | L4: {=_xlfn.LET( _xlpm.name, TRIM(B4), _xlpm.nameClean, SUBSTITUTE(SUBSTITUTE(_xlpm.name, ", Jr.", ""), " III", ""), _xlpm.parts, _xlfn.TEXTSPLIT(_xlpm.nameClean, " "), _xlpm.count, COUNTA(_xlpm.parts), _xlpm.first, INDEX(_xlpm.parts, 1), _xlpm.last, INDEX(_xlpm.parts, _xlpm.count), _xlpm.result, _xlpm.last & "_" & _xlpm.first & "_25", _xlpm.result )} -> Conerly_Tim_25 | M4: WR | N4: =Table5[[#This Row],[Yr.]] -> Sr.
A5: 0 | B5: Ricky Lee III | C5: CB | D5: 45787 | E5: 162 | F5: So. | G5: TR | H5: Atlanta, Ga. | I5: Cedar Grove HS | J5: UAB | K5: {=_xlfn.LET( _xlpm.name, TRIM(B5), _xlpm.nameClean, SUBSTITUTE(SUBSTITUTE(_xlpm.name, ", Jr.", ""), " III", ""), _xlpm.parts, _xlfn.TEXTSPLIT(_xlpm.nameClean, " "), _xlpm.count, COUNTA(_xlpm.parts), _xlpm.first, INDEX(_xlpm.parts, 1), _xlpm.last, INDEX(_xlpm.parts, _xlpm.count), _xlpm.first & " " & _xlpm.last )} -> Ricky Lee | L5: {=_xlfn.LET( _xlpm.name, TRIM(B5), _xlpm.nameClean, SUBSTITUTE(SUBSTITUTE(_xlpm.name, ", Jr.", ""), " III", ""), _xlpm.parts, _xlfn.TEXTSPLIT(_xlpm.nameClean, " "), _xlpm.count, COUNTA(_xlpm.parts), _xlpm.first, INDEX(_xlpm.parts, 1), _xlpm.last, INDEX(_xlpm.parts, _xlpm.count), _xlpm.result, _xlpm.last & "_" & _xlpm.first & "_25", _xlpm.result )} -> Lee_Ricky_25 | M5: CB | N5: =Table5[[#This Row],[Yr.]] -> So.
A6: 17 | B6: Ajon Bryant | C6: RB | D6: 45783 | E6: 162 | F6: R-Fr. | G6: RS | H6: Santa Ana, Calif. | I6: Mater Dei HS | K6: {=_xlfn.LET( _xlpm.name, TRIM(B6), _xlpm.nameClean, SUBSTITUTE(SUBSTITUTE(_xlpm.name, ", Jr.", ""), " III", ""), _xlpm.parts, _xlfn.TEXTSPLIT(_xlpm.nameClean, " "), _xlpm.count, COUNTA(_xlpm.parts), _xlpm.first, INDEX(_xlpm.parts, 1), _xlpm.last, INDEX(_xlpm.parts, _xlpm.count), _xlpm.first & " " & _xlpm.last )} -> Ajon Bryant | L6: {=_xlfn.LET( _xlpm.name, TRIM(B6), _xlpm.nameClean, SUBSTITUTE(SUBSTITUTE(_xlpm.name, ", Jr.", ""), " III", ""), _xlpm.parts, _xlfn.TEXTSPLIT(_xlpm.nameClean, " "), _xlpm.count, COUNTA(_xlpm.parts), _xlpm.first, INDEX(_xlpm.parts, 1), _xlpm.last, INDEX(_xlpm.parts, _xlpm.count), _xlpm.result, _xlpm.last & "_" & _xlpm.first & "_25", _xlpm.result )} -> Bryant_Ajon_25 | M6: RB | N6: =Table5[[#This Row],[Yr.]] -> R-Fr.
